2021-07-13 13:33:07,211 ERROR scheduler Exception in Enqueue Events for Site library.test
Traceback (most recent call last):
  File "/home/brenda/Desktop/frappe-bench/env/lib/python3.6/site-packages/pymysql/connections.py", line 614, in connect
    (self.host, self.port), self.connect_timeout, **kwargs
  File "/usr/lib/python3.6/socket.py", line 724, in create_connection
    raise err
  File "/usr/lib/python3.6/socket.py", line 713, in create_connection
    sock.connect(sa)
ConnectionRefusedError: [Errno 111] Connection refused

During handling of the above exception, another exception occurred:

Traceback (most recent call last):
  File "/home/brenda/Desktop/frappe-bench/apps/frappe/frappe/utils/scheduler.py", line 62, in enqueue_events_for_site
    if is_scheduler_inactive():
  File "/home/brenda/Desktop/frappe-bench/apps/frappe/frappe/utils/scheduler.py", line 95, in is_scheduler_inactive
    if is_scheduler_disabled():
  File "/home/brenda/Desktop/frappe-bench/apps/frappe/frappe/utils/scheduler.py", line 104, in is_scheduler_disabled
    return not frappe.utils.cint(frappe.db.get_single_value("System Settings", "enable_scheduler"))
  File "/home/brenda/Desktop/frappe-bench/apps/frappe/frappe/database/database.py", line 550, in get_single_value
    `tabSingles` where `doctype`=%s and `field`=%s""", (doctype, fieldname))
  File "/home/brenda/Desktop/frappe-bench/apps/frappe/frappe/database/database.py", line 111, in sql
    self.connect()
  File "/home/brenda/Desktop/frappe-bench/apps/frappe/frappe/database/database.py", line 64, in connect
    self._conn = self.get_connection()
  File "/home/brenda/Desktop/frappe-bench/apps/frappe/frappe/database/mariadb/database.py", line 80, in get_connection
    local_infile=frappe.conf.local_infile
  File "/home/brenda/Desktop/frappe-bench/env/lib/python3.6/site-packages/pymysql/connections.py", line 353, in __init__
    self.connect()
  File "/home/brenda/Desktop/frappe-bench/env/lib/python3.6/site-packages/pymysql/connections.py", line 664, in connect
    raise exc
pymysql.err.OperationalError: (2003, "Can't connect to MySQL server on '127.0.0.1' ([Errno 111] Connection refused)")

2021-07-13 13:34:07,296 ERROR scheduler Exception in Enqueue Events for Site library.test
Traceback (most recent call last):
  File "/home/brenda/Desktop/frappe-bench/env/lib/python3.6/site-packages/pymysql/connections.py", line 614, in connect
    (self.host, self.port), self.connect_timeout, **kwargs
  File "/usr/lib/python3.6/socket.py", line 724, in create_connection
    raise err
  File "/usr/lib/python3.6/socket.py", line 713, in create_connection
    sock.connect(sa)
ConnectionRefusedError: [Errno 111] Connection refused

During handling of the above exception, another exception occurred:

Traceback (most recent call last):
  File "/home/brenda/Desktop/frappe-bench/apps/frappe/frappe/utils/scheduler.py", line 62, in enqueue_events_for_site
    if is_scheduler_inactive():
  File "/home/brenda/Desktop/frappe-bench/apps/frappe/frappe/utils/scheduler.py", line 95, in is_scheduler_inactive
    if is_scheduler_disabled():
  File "/home/brenda/Desktop/frappe-bench/apps/frappe/frappe/utils/scheduler.py", line 104, in is_scheduler_disabled
    return not frappe.utils.cint(frappe.db.get_single_value("System Settings", "enable_scheduler"))
  File "/home/brenda/Desktop/frappe-bench/apps/frappe/frappe/database/database.py", line 550, in get_single_value
    `tabSingles` where `doctype`=%s and `field`=%s""", (doctype, fieldname))
  File "/home/brenda/Desktop/frappe-bench/apps/frappe/frappe/database/database.py", line 111, in sql
    self.connect()
  File "/home/brenda/Desktop/frappe-bench/apps/frappe/frappe/database/database.py", line 64, in connect
    self._conn = self.get_connection()
  File "/home/brenda/Desktop/frappe-bench/apps/frappe/frappe/database/mariadb/database.py", line 80, in get_connection
    local_infile=frappe.conf.local_infile
  File "/home/brenda/Desktop/frappe-bench/env/lib/python3.6/site-packages/pymysql/connections.py", line 353, in __init__
    self.connect()
  File "/home/brenda/Desktop/frappe-bench/env/lib/python3.6/site-packages/pymysql/connections.py", line 664, in connect
    raise exc
pymysql.err.OperationalError: (2003, "Can't connect to MySQL server on '127.0.0.1' ([Errno 111] Connection refused)")

2021-07-13 13:35:07,378 ERROR scheduler Exception in Enqueue Events for Site library.test
Traceback (most recent call last):
  File "/home/brenda/Desktop/frappe-bench/env/lib/python3.6/site-packages/pymysql/connections.py", line 614, in connect
    (self.host, self.port), self.connect_timeout, **kwargs
  File "/usr/lib/python3.6/socket.py", line 724, in create_connection
    raise err
  File "/usr/lib/python3.6/socket.py", line 713, in create_connection
    sock.connect(sa)
ConnectionRefusedError: [Errno 111] Connection refused

During handling of the above exception, another exception occurred:

Traceback (most recent call last):
  File "/home/brenda/Desktop/frappe-bench/apps/frappe/frappe/utils/scheduler.py", line 62, in enqueue_events_for_site
    if is_scheduler_inactive():
  File "/home/brenda/Desktop/frappe-bench/apps/frappe/frappe/utils/scheduler.py", line 95, in is_scheduler_inactive
    if is_scheduler_disabled():
  File "/home/brenda/Desktop/frappe-bench/apps/frappe/frappe/utils/scheduler.py", line 104, in is_scheduler_disabled
    return not frappe.utils.cint(frappe.db.get_single_value("System Settings", "enable_scheduler"))
  File "/home/brenda/Desktop/frappe-bench/apps/frappe/frappe/database/database.py", line 550, in get_single_value
    `tabSingles` where `doctype`=%s and `field`=%s""", (doctype, fieldname))
  File "/home/brenda/Desktop/frappe-bench/apps/frappe/frappe/database/database.py", line 111, in sql
    self.connect()
  File "/home/brenda/Desktop/frappe-bench/apps/frappe/frappe/database/database.py", line 64, in connect
    self._conn = self.get_connection()
  File "/home/brenda/Desktop/frappe-bench/apps/frappe/frappe/database/mariadb/database.py", line 80, in get_connection
    local_infile=frappe.conf.local_infile
  File "/home/brenda/Desktop/frappe-bench/env/lib/python3.6/site-packages/pymysql/connections.py", line 353, in __init__
    self.connect()
  File "/home/brenda/Desktop/frappe-bench/env/lib/python3.6/site-packages/pymysql/connections.py", line 664, in connect
    raise exc
pymysql.err.OperationalError: (2003, "Can't connect to MySQL server on '127.0.0.1' ([Errno 111] Connection refused)")

2021-07-13 13:36:07,460 ERROR scheduler Exception in Enqueue Events for Site library.test
Traceback (most recent call last):
  File "/home/brenda/Desktop/frappe-bench/env/lib/python3.6/site-packages/pymysql/connections.py", line 614, in connect
    (self.host, self.port), self.connect_timeout, **kwargs
  File "/usr/lib/python3.6/socket.py", line 724, in create_connection
    raise err
  File "/usr/lib/python3.6/socket.py", line 713, in create_connection
    sock.connect(sa)
ConnectionRefusedError: [Errno 111] Connection refused

During handling of the above exception, another exception occurred:

Traceback (most recent call last):
  File "/home/brenda/Desktop/frappe-bench/apps/frappe/frappe/utils/scheduler.py", line 62, in enqueue_events_for_site
    if is_scheduler_inactive():
  File "/home/brenda/Desktop/frappe-bench/apps/frappe/frappe/utils/scheduler.py", line 95, in is_scheduler_inactive
    if is_scheduler_disabled():
  File "/home/brenda/Desktop/frappe-bench/apps/frappe/frappe/utils/scheduler.py", line 104, in is_scheduler_disabled
    return not frappe.utils.cint(frappe.db.get_single_value("System Settings", "enable_scheduler"))
  File "/home/brenda/Desktop/frappe-bench/apps/frappe/frappe/database/database.py", line 550, in get_single_value
    `tabSingles` where `doctype`=%s and `field`=%s""", (doctype, fieldname))
  File "/home/brenda/Desktop/frappe-bench/apps/frappe/frappe/database/database.py", line 111, in sql
    self.connect()
  File "/home/brenda/Desktop/frappe-bench/apps/frappe/frappe/database/database.py", line 64, in connect
    self._conn = self.get_connection()
  File "/home/brenda/Desktop/frappe-bench/apps/frappe/frappe/database/mariadb/database.py", line 80, in get_connection
    local_infile=frappe.conf.local_infile
  File "/home/brenda/Desktop/frappe-bench/env/lib/python3.6/site-packages/pymysql/connections.py", line 353, in __init__
    self.connect()
  File "/home/brenda/Desktop/frappe-bench/env/lib/python3.6/site-packages/pymysql/connections.py", line 664, in connect
    raise exc
pymysql.err.OperationalError: (2003, "Can't connect to MySQL server on '127.0.0.1' ([Errno 111] Connection refused)")

2021-07-13 13:37:07,542 ERROR scheduler Exception in Enqueue Events for Site library.test
Traceback (most recent call last):
  File "/home/brenda/Desktop/frappe-bench/env/lib/python3.6/site-packages/pymysql/connections.py", line 614, in connect
    (self.host, self.port), self.connect_timeout, **kwargs
  File "/usr/lib/python3.6/socket.py", line 724, in create_connection
    raise err
  File "/usr/lib/python3.6/socket.py", line 713, in create_connection
    sock.connect(sa)
ConnectionRefusedError: [Errno 111] Connection refused

During handling of the above exception, another exception occurred:

Traceback (most recent call last):
  File "/home/brenda/Desktop/frappe-bench/apps/frappe/frappe/utils/scheduler.py", line 62, in enqueue_events_for_site
    if is_scheduler_inactive():
  File "/home/brenda/Desktop/frappe-bench/apps/frappe/frappe/utils/scheduler.py", line 95, in is_scheduler_inactive
    if is_scheduler_disabled():
  File "/home/brenda/Desktop/frappe-bench/apps/frappe/frappe/utils/scheduler.py", line 104, in is_scheduler_disabled
    return not frappe.utils.cint(frappe.db.get_single_value("System Settings", "enable_scheduler"))
  File "/home/brenda/Desktop/frappe-bench/apps/frappe/frappe/database/database.py", line 550, in get_single_value
    `tabSingles` where `doctype`=%s and `field`=%s""", (doctype, fieldname))
  File "/home/brenda/Desktop/frappe-bench/apps/frappe/frappe/database/database.py", line 111, in sql
    self.connect()
  File "/home/brenda/Desktop/frappe-bench/apps/frappe/frappe/database/database.py", line 64, in connect
    self._conn = self.get_connection()
  File "/home/brenda/Desktop/frappe-bench/apps/frappe/frappe/database/mariadb/database.py", line 80, in get_connection
    local_infile=frappe.conf.local_infile
  File "/home/brenda/Desktop/frappe-bench/env/lib/python3.6/site-packages/pymysql/connections.py", line 353, in __init__
    self.connect()
  File "/home/brenda/Desktop/frappe-bench/env/lib/python3.6/site-packages/pymysql/connections.py", line 664, in connect
    raise exc
pymysql.err.OperationalError: (2003, "Can't connect to MySQL server on '127.0.0.1' ([Errno 111] Connection refused)")

2021-07-13 13:38:07,616 ERROR scheduler Exception in Enqueue Events for Site library.test
Traceback (most recent call last):
  File "/home/brenda/Desktop/frappe-bench/env/lib/python3.6/site-packages/pymysql/connections.py", line 614, in connect
    (self.host, self.port), self.connect_timeout, **kwargs
  File "/usr/lib/python3.6/socket.py", line 724, in create_connection
    raise err
  File "/usr/lib/python3.6/socket.py", line 713, in create_connection
    sock.connect(sa)
ConnectionRefusedError: [Errno 111] Connection refused

During handling of the above exception, another exception occurred:

Traceback (most recent call last):
  File "/home/brenda/Desktop/frappe-bench/apps/frappe/frappe/utils/scheduler.py", line 62, in enqueue_events_for_site
    if is_scheduler_inactive():
  File "/home/brenda/Desktop/frappe-bench/apps/frappe/frappe/utils/scheduler.py", line 95, in is_scheduler_inactive
    if is_scheduler_disabled():
  File "/home/brenda/Desktop/frappe-bench/apps/frappe/frappe/utils/scheduler.py", line 104, in is_scheduler_disabled
    return not frappe.utils.cint(frappe.db.get_single_value("System Settings", "enable_scheduler"))
  File "/home/brenda/Desktop/frappe-bench/apps/frappe/frappe/database/database.py", line 550, in get_single_value
    `tabSingles` where `doctype`=%s and `field`=%s""", (doctype, fieldname))
  File "/home/brenda/Desktop/frappe-bench/apps/frappe/frappe/database/database.py", line 111, in sql
    self.connect()
  File "/home/brenda/Desktop/frappe-bench/apps/frappe/frappe/database/database.py", line 64, in connect
    self._conn = self.get_connection()
  File "/home/brenda/Desktop/frappe-bench/apps/frappe/frappe/database/mariadb/database.py", line 80, in get_connection
    local_infile=frappe.conf.local_infile
  File "/home/brenda/Desktop/frappe-bench/env/lib/python3.6/site-packages/pymysql/connections.py", line 353, in __init__
    self.connect()
  File "/home/brenda/Desktop/frappe-bench/env/lib/python3.6/site-packages/pymysql/connections.py", line 664, in connect
    raise exc
pymysql.err.OperationalError: (2003, "Can't connect to MySQL server on '127.0.0.1' ([Errno 111] Connection refused)")

2021-07-13 13:39:07,689 ERROR scheduler Exception in Enqueue Events for Site library.test
Traceback (most recent call last):
  File "/home/brenda/Desktop/frappe-bench/env/lib/python3.6/site-packages/pymysql/connections.py", line 614, in connect
    (self.host, self.port), self.connect_timeout, **kwargs
  File "/usr/lib/python3.6/socket.py", line 724, in create_connection
    raise err
  File "/usr/lib/python3.6/socket.py", line 713, in create_connection
    sock.connect(sa)
ConnectionRefusedError: [Errno 111] Connection refused

During handling of the above exception, another exception occurred:

Traceback (most recent call last):
  File "/home/brenda/Desktop/frappe-bench/apps/frappe/frappe/utils/scheduler.py", line 62, in enqueue_events_for_site
    if is_scheduler_inactive():
  File "/home/brenda/Desktop/frappe-bench/apps/frappe/frappe/utils/scheduler.py", line 95, in is_scheduler_inactive
    if is_scheduler_disabled():
  File "/home/brenda/Desktop/frappe-bench/apps/frappe/frappe/utils/scheduler.py", line 104, in is_scheduler_disabled
    return not frappe.utils.cint(frappe.db.get_single_value("System Settings", "enable_scheduler"))
  File "/home/brenda/Desktop/frappe-bench/apps/frappe/frappe/database/database.py", line 550, in get_single_value
    `tabSingles` where `doctype`=%s and `field`=%s""", (doctype, fieldname))
  File "/home/brenda/Desktop/frappe-bench/apps/frappe/frappe/database/database.py", line 111, in sql
    self.connect()
  File "/home/brenda/Desktop/frappe-bench/apps/frappe/frappe/database/database.py", line 64, in connect
    self._conn = self.get_connection()
  File "/home/brenda/Desktop/frappe-bench/apps/frappe/frappe/database/mariadb/database.py", line 80, in get_connection
    local_infile=frappe.conf.local_infile
  File "/home/brenda/Desktop/frappe-bench/env/lib/python3.6/site-packages/pymysql/connections.py", line 353, in __init__
    self.connect()
  File "/home/brenda/Desktop/frappe-bench/env/lib/python3.6/site-packages/pymysql/connections.py", line 664, in connect
    raise exc
pymysql.err.OperationalError: (2003, "Can't connect to MySQL server on '127.0.0.1' ([Errno 111] Connection refused)")

2021-07-13 13:40:07,770 ERROR scheduler Exception in Enqueue Events for Site library.test
Traceback (most recent call last):
  File "/home/brenda/Desktop/frappe-bench/env/lib/python3.6/site-packages/pymysql/connections.py", line 614, in connect
    (self.host, self.port), self.connect_timeout, **kwargs
  File "/usr/lib/python3.6/socket.py", line 724, in create_connection
    raise err
  File "/usr/lib/python3.6/socket.py", line 713, in create_connection
    sock.connect(sa)
ConnectionRefusedError: [Errno 111] Connection refused

During handling of the above exception, another exception occurred:

Traceback (most recent call last):
  File "/home/brenda/Desktop/frappe-bench/apps/frappe/frappe/utils/scheduler.py", line 62, in enqueue_events_for_site
    if is_scheduler_inactive():
  File "/home/brenda/Desktop/frappe-bench/apps/frappe/frappe/utils/scheduler.py", line 95, in is_scheduler_inactive
    if is_scheduler_disabled():
  File "/home/brenda/Desktop/frappe-bench/apps/frappe/frappe/utils/scheduler.py", line 104, in is_scheduler_disabled
    return not frappe.utils.cint(frappe.db.get_single_value("System Settings", "enable_scheduler"))
  File "/home/brenda/Desktop/frappe-bench/apps/frappe/frappe/database/database.py", line 550, in get_single_value
    `tabSingles` where `doctype`=%s and `field`=%s""", (doctype, fieldname))
  File "/home/brenda/Desktop/frappe-bench/apps/frappe/frappe/database/database.py", line 111, in sql
    self.connect()
  File "/home/brenda/Desktop/frappe-bench/apps/frappe/frappe/database/database.py", line 64, in connect
    self._conn = self.get_connection()
  File "/home/brenda/Desktop/frappe-bench/apps/frappe/frappe/database/mariadb/database.py", line 80, in get_connection
    local_infile=frappe.conf.local_infile
  File "/home/brenda/Desktop/frappe-bench/env/lib/python3.6/site-packages/pymysql/connections.py", line 353, in __init__
    self.connect()
  File "/home/brenda/Desktop/frappe-bench/env/lib/python3.6/site-packages/pymysql/connections.py", line 664, in connect
    raise exc
pymysql.err.OperationalError: (2003, "Can't connect to MySQL server on '127.0.0.1' ([Errno 111] Connection refused)")

2021-07-13 13:41:07,853 ERROR scheduler Exception in Enqueue Events for Site library.test
Traceback (most recent call last):
  File "/home/brenda/Desktop/frappe-bench/env/lib/python3.6/site-packages/pymysql/connections.py", line 614, in connect
    (self.host, self.port), self.connect_timeout, **kwargs
  File "/usr/lib/python3.6/socket.py", line 724, in create_connection
    raise err
  File "/usr/lib/python3.6/socket.py", line 713, in create_connection
    sock.connect(sa)
ConnectionRefusedError: [Errno 111] Connection refused

During handling of the above exception, another exception occurred:

Traceback (most recent call last):
  File "/home/brenda/Desktop/frappe-bench/apps/frappe/frappe/utils/scheduler.py", line 62, in enqueue_events_for_site
    if is_scheduler_inactive():
  File "/home/brenda/Desktop/frappe-bench/apps/frappe/frappe/utils/scheduler.py", line 95, in is_scheduler_inactive
    if is_scheduler_disabled():
  File "/home/brenda/Desktop/frappe-bench/apps/frappe/frappe/utils/scheduler.py", line 104, in is_scheduler_disabled
    return not frappe.utils.cint(frappe.db.get_single_value("System Settings", "enable_scheduler"))
  File "/home/brenda/Desktop/frappe-bench/apps/frappe/frappe/database/database.py", line 550, in get_single_value
    `tabSingles` where `doctype`=%s and `field`=%s""", (doctype, fieldname))
  File "/home/brenda/Desktop/frappe-bench/apps/frappe/frappe/database/database.py", line 111, in sql
    self.connect()
  File "/home/brenda/Desktop/frappe-bench/apps/frappe/frappe/database/database.py", line 64, in connect
    self._conn = self.get_connection()
  File "/home/brenda/Desktop/frappe-bench/apps/frappe/frappe/database/mariadb/database.py", line 80, in get_connection
    local_infile=frappe.conf.local_infile
  File "/home/brenda/Desktop/frappe-bench/env/lib/python3.6/site-packages/pymysql/connections.py", line 353, in __init__
    self.connect()
  File "/home/brenda/Desktop/frappe-bench/env/lib/python3.6/site-packages/pymysql/connections.py", line 664, in connect
    raise exc
pymysql.err.OperationalError: (2003, "Can't connect to MySQL server on '127.0.0.1' ([Errno 111] Connection refused)")

2021-07-13 13:42:07,937 ERROR scheduler Exception in Enqueue Events for Site library.test
Traceback (most recent call last):
  File "/home/brenda/Desktop/frappe-bench/env/lib/python3.6/site-packages/pymysql/connections.py", line 614, in connect
    (self.host, self.port), self.connect_timeout, **kwargs
  File "/usr/lib/python3.6/socket.py", line 724, in create_connection
    raise err
  File "/usr/lib/python3.6/socket.py", line 713, in create_connection
    sock.connect(sa)
ConnectionRefusedError: [Errno 111] Connection refused

During handling of the above exception, another exception occurred:

Traceback (most recent call last):
  File "/home/brenda/Desktop/frappe-bench/apps/frappe/frappe/utils/scheduler.py", line 62, in enqueue_events_for_site
    if is_scheduler_inactive():
  File "/home/brenda/Desktop/frappe-bench/apps/frappe/frappe/utils/scheduler.py", line 95, in is_scheduler_inactive
    if is_scheduler_disabled():
  File "/home/brenda/Desktop/frappe-bench/apps/frappe/frappe/utils/scheduler.py", line 104, in is_scheduler_disabled
    return not frappe.utils.cint(frappe.db.get_single_value("System Settings", "enable_scheduler"))
  File "/home/brenda/Desktop/frappe-bench/apps/frappe/frappe/database/database.py", line 550, in get_single_value
    `tabSingles` where `doctype`=%s and `field`=%s""", (doctype, fieldname))
  File "/home/brenda/Desktop/frappe-bench/apps/frappe/frappe/database/database.py", line 111, in sql
    self.connect()
  File "/home/brenda/Desktop/frappe-bench/apps/frappe/frappe/database/database.py", line 64, in connect
    self._conn = self.get_connection()
  File "/home/brenda/Desktop/frappe-bench/apps/frappe/frappe/database/mariadb/database.py", line 80, in get_connection
    local_infile=frappe.conf.local_infile
  File "/home/brenda/Desktop/frappe-bench/env/lib/python3.6/site-packages/pymysql/connections.py", line 353, in __init__
    self.connect()
  File "/home/brenda/Desktop/frappe-bench/env/lib/python3.6/site-packages/pymysql/connections.py", line 664, in connect
    raise exc
pymysql.err.OperationalError: (2003, "Can't connect to MySQL server on '127.0.0.1' ([Errno 111] Connection refused)")

2021-07-13 13:43:08,017 ERROR scheduler Exception in Enqueue Events for Site library.test
Traceback (most recent call last):
  File "/home/brenda/Desktop/frappe-bench/env/lib/python3.6/site-packages/pymysql/connections.py", line 614, in connect
    (self.host, self.port), self.connect_timeout, **kwargs
  File "/usr/lib/python3.6/socket.py", line 724, in create_connection
    raise err
  File "/usr/lib/python3.6/socket.py", line 713, in create_connection
    sock.connect(sa)
ConnectionRefusedError: [Errno 111] Connection refused

During handling of the above exception, another exception occurred:

Traceback (most recent call last):
  File "/home/brenda/Desktop/frappe-bench/apps/frappe/frappe/utils/scheduler.py", line 62, in enqueue_events_for_site
    if is_scheduler_inactive():
  File "/home/brenda/Desktop/frappe-bench/apps/frappe/frappe/utils/scheduler.py", line 95, in is_scheduler_inactive
    if is_scheduler_disabled():
  File "/home/brenda/Desktop/frappe-bench/apps/frappe/frappe/utils/scheduler.py", line 104, in is_scheduler_disabled
    return not frappe.utils.cint(frappe.db.get_single_value("System Settings", "enable_scheduler"))
  File "/home/brenda/Desktop/frappe-bench/apps/frappe/frappe/database/database.py", line 550, in get_single_value
    `tabSingles` where `doctype`=%s and `field`=%s""", (doctype, fieldname))
  File "/home/brenda/Desktop/frappe-bench/apps/frappe/frappe/database/database.py", line 111, in sql
    self.connect()
  File "/home/brenda/Desktop/frappe-bench/apps/frappe/frappe/database/database.py", line 64, in connect
    self._conn = self.get_connection()
  File "/home/brenda/Desktop/frappe-bench/apps/frappe/frappe/database/mariadb/database.py", line 80, in get_connection
    local_infile=frappe.conf.local_infile
  File "/home/brenda/Desktop/frappe-bench/env/lib/python3.6/site-packages/pymysql/connections.py", line 353, in __init__
    self.connect()
  File "/home/brenda/Desktop/frappe-bench/env/lib/python3.6/site-packages/pymysql/connections.py", line 664, in connect
    raise exc
pymysql.err.OperationalError: (2003, "Can't connect to MySQL server on '127.0.0.1' ([Errno 111] Connection refused)")

2021-07-13 13:44:08,104 ERROR scheduler Exception in Enqueue Events for Site library.test
Traceback (most recent call last):
  File "/home/brenda/Desktop/frappe-bench/env/lib/python3.6/site-packages/pymysql/connections.py", line 614, in connect
    (self.host, self.port), self.connect_timeout, **kwargs
  File "/usr/lib/python3.6/socket.py", line 724, in create_connection
    raise err
  File "/usr/lib/python3.6/socket.py", line 713, in create_connection
    sock.connect(sa)
ConnectionRefusedError: [Errno 111] Connection refused

During handling of the above exception, another exception occurred:

Traceback (most recent call last):
  File "/home/brenda/Desktop/frappe-bench/apps/frappe/frappe/utils/scheduler.py", line 62, in enqueue_events_for_site
    if is_scheduler_inactive():
  File "/home/brenda/Desktop/frappe-bench/apps/frappe/frappe/utils/scheduler.py", line 95, in is_scheduler_inactive
    if is_scheduler_disabled():
  File "/home/brenda/Desktop/frappe-bench/apps/frappe/frappe/utils/scheduler.py", line 104, in is_scheduler_disabled
    return not frappe.utils.cint(frappe.db.get_single_value("System Settings", "enable_scheduler"))
  File "/home/brenda/Desktop/frappe-bench/apps/frappe/frappe/database/database.py", line 550, in get_single_value
    `tabSingles` where `doctype`=%s and `field`=%s""", (doctype, fieldname))
  File "/home/brenda/Desktop/frappe-bench/apps/frappe/frappe/database/database.py", line 111, in sql
    self.connect()
  File "/home/brenda/Desktop/frappe-bench/apps/frappe/frappe/database/database.py", line 64, in connect
    self._conn = self.get_connection()
  File "/home/brenda/Desktop/frappe-bench/apps/frappe/frappe/database/mariadb/database.py", line 80, in get_connection
    local_infile=frappe.conf.local_infile
  File "/home/brenda/Desktop/frappe-bench/env/lib/python3.6/site-packages/pymysql/connections.py", line 353, in __init__
    self.connect()
  File "/home/brenda/Desktop/frappe-bench/env/lib/python3.6/site-packages/pymysql/connections.py", line 664, in connect
    raise exc
pymysql.err.OperationalError: (2003, "Can't connect to MySQL server on '127.0.0.1' ([Errno 111] Connection refused)")

2021-07-13 13:45:08,176 ERROR scheduler Exception in Enqueue Events for Site library.test
Traceback (most recent call last):
  File "/home/brenda/Desktop/frappe-bench/env/lib/python3.6/site-packages/pymysql/connections.py", line 614, in connect
    (self.host, self.port), self.connect_timeout, **kwargs
  File "/usr/lib/python3.6/socket.py", line 724, in create_connection
    raise err
  File "/usr/lib/python3.6/socket.py", line 713, in create_connection
    sock.connect(sa)
ConnectionRefusedError: [Errno 111] Connection refused

During handling of the above exception, another exception occurred:

Traceback (most recent call last):
  File "/home/brenda/Desktop/frappe-bench/apps/frappe/frappe/utils/scheduler.py", line 62, in enqueue_events_for_site
    if is_scheduler_inactive():
  File "/home/brenda/Desktop/frappe-bench/apps/frappe/frappe/utils/scheduler.py", line 95, in is_scheduler_inactive
    if is_scheduler_disabled():
  File "/home/brenda/Desktop/frappe-bench/apps/frappe/frappe/utils/scheduler.py", line 104, in is_scheduler_disabled
    return not frappe.utils.cint(frappe.db.get_single_value("System Settings", "enable_scheduler"))
  File "/home/brenda/Desktop/frappe-bench/apps/frappe/frappe/database/database.py", line 550, in get_single_value
    `tabSingles` where `doctype`=%s and `field`=%s""", (doctype, fieldname))
  File "/home/brenda/Desktop/frappe-bench/apps/frappe/frappe/database/database.py", line 111, in sql
    self.connect()
  File "/home/brenda/Desktop/frappe-bench/apps/frappe/frappe/database/database.py", line 64, in connect
    self._conn = self.get_connection()
  File "/home/brenda/Desktop/frappe-bench/apps/frappe/frappe/database/mariadb/database.py", line 80, in get_connection
    local_infile=frappe.conf.local_infile
  File "/home/brenda/Desktop/frappe-bench/env/lib/python3.6/site-packages/pymysql/connections.py", line 353, in __init__
    self.connect()
  File "/home/brenda/Desktop/frappe-bench/env/lib/python3.6/site-packages/pymysql/connections.py", line 664, in connect
    raise exc
pymysql.err.OperationalError: (2003, "Can't connect to MySQL server on '127.0.0.1' ([Errno 111] Connection refused)")

2021-07-13 13:46:08,252 ERROR scheduler Exception in Enqueue Events for Site library.test
Traceback (most recent call last):
  File "/home/brenda/Desktop/frappe-bench/env/lib/python3.6/site-packages/pymysql/connections.py", line 614, in connect
    (self.host, self.port), self.connect_timeout, **kwargs
  File "/usr/lib/python3.6/socket.py", line 724, in create_connection
    raise err
  File "/usr/lib/python3.6/socket.py", line 713, in create_connection
    sock.connect(sa)
ConnectionRefusedError: [Errno 111] Connection refused

During handling of the above exception, another exception occurred:

Traceback (most recent call last):
  File "/home/brenda/Desktop/frappe-bench/apps/frappe/frappe/utils/scheduler.py", line 62, in enqueue_events_for_site
    if is_scheduler_inactive():
  File "/home/brenda/Desktop/frappe-bench/apps/frappe/frappe/utils/scheduler.py", line 95, in is_scheduler_inactive
    if is_scheduler_disabled():
  File "/home/brenda/Desktop/frappe-bench/apps/frappe/frappe/utils/scheduler.py", line 104, in is_scheduler_disabled
    return not frappe.utils.cint(frappe.db.get_single_value("System Settings", "enable_scheduler"))
  File "/home/brenda/Desktop/frappe-bench/apps/frappe/frappe/database/database.py", line 550, in get_single_value
    `tabSingles` where `doctype`=%s and `field`=%s""", (doctype, fieldname))
  File "/home/brenda/Desktop/frappe-bench/apps/frappe/frappe/database/database.py", line 111, in sql
    self.connect()
  File "/home/brenda/Desktop/frappe-bench/apps/frappe/frappe/database/database.py", line 64, in connect
    self._conn = self.get_connection()
  File "/home/brenda/Desktop/frappe-bench/apps/frappe/frappe/database/mariadb/database.py", line 80, in get_connection
    local_infile=frappe.conf.local_infile
  File "/home/brenda/Desktop/frappe-bench/env/lib/python3.6/site-packages/pymysql/connections.py", line 353, in __init__
    self.connect()
  File "/home/brenda/Desktop/frappe-bench/env/lib/python3.6/site-packages/pymysql/connections.py", line 664, in connect
    raise exc
pymysql.err.OperationalError: (2003, "Can't connect to MySQL server on '127.0.0.1' ([Errno 111] Connection refused)")

2021-07-13 13:47:08,333 ERROR scheduler Exception in Enqueue Events for Site library.test
Traceback (most recent call last):
  File "/home/brenda/Desktop/frappe-bench/env/lib/python3.6/site-packages/pymysql/connections.py", line 614, in connect
    (self.host, self.port), self.connect_timeout, **kwargs
  File "/usr/lib/python3.6/socket.py", line 724, in create_connection
    raise err
  File "/usr/lib/python3.6/socket.py", line 713, in create_connection
    sock.connect(sa)
ConnectionRefusedError: [Errno 111] Connection refused

During handling of the above exception, another exception occurred:

Traceback (most recent call last):
  File "/home/brenda/Desktop/frappe-bench/apps/frappe/frappe/utils/scheduler.py", line 62, in enqueue_events_for_site
    if is_scheduler_inactive():
  File "/home/brenda/Desktop/frappe-bench/apps/frappe/frappe/utils/scheduler.py", line 95, in is_scheduler_inactive
    if is_scheduler_disabled():
  File "/home/brenda/Desktop/frappe-bench/apps/frappe/frappe/utils/scheduler.py", line 104, in is_scheduler_disabled
    return not frappe.utils.cint(frappe.db.get_single_value("System Settings", "enable_scheduler"))
  File "/home/brenda/Desktop/frappe-bench/apps/frappe/frappe/database/database.py", line 550, in get_single_value
    `tabSingles` where `doctype`=%s and `field`=%s""", (doctype, fieldname))
  File "/home/brenda/Desktop/frappe-bench/apps/frappe/frappe/database/database.py", line 111, in sql
    self.connect()
  File "/home/brenda/Desktop/frappe-bench/apps/frappe/frappe/database/database.py", line 64, in connect
    self._conn = self.get_connection()
  File "/home/brenda/Desktop/frappe-bench/apps/frappe/frappe/database/mariadb/database.py", line 80, in get_connection
    local_infile=frappe.conf.local_infile
  File "/home/brenda/Desktop/frappe-bench/env/lib/python3.6/site-packages/pymysql/connections.py", line 353, in __init__
    self.connect()
  File "/home/brenda/Desktop/frappe-bench/env/lib/python3.6/site-packages/pymysql/connections.py", line 664, in connect
    raise exc
pymysql.err.OperationalError: (2003, "Can't connect to MySQL server on '127.0.0.1' ([Errno 111] Connection refused)")

2021-07-13 13:48:08,414 ERROR scheduler Exception in Enqueue Events for Site library.test
Traceback (most recent call last):
  File "/home/brenda/Desktop/frappe-bench/env/lib/python3.6/site-packages/pymysql/connections.py", line 614, in connect
    (self.host, self.port), self.connect_timeout, **kwargs
  File "/usr/lib/python3.6/socket.py", line 724, in create_connection
    raise err
  File "/usr/lib/python3.6/socket.py", line 713, in create_connection
    sock.connect(sa)
ConnectionRefusedError: [Errno 111] Connection refused

During handling of the above exception, another exception occurred:

Traceback (most recent call last):
  File "/home/brenda/Desktop/frappe-bench/apps/frappe/frappe/utils/scheduler.py", line 62, in enqueue_events_for_site
    if is_scheduler_inactive():
  File "/home/brenda/Desktop/frappe-bench/apps/frappe/frappe/utils/scheduler.py", line 95, in is_scheduler_inactive
    if is_scheduler_disabled():
  File "/home/brenda/Desktop/frappe-bench/apps/frappe/frappe/utils/scheduler.py", line 104, in is_scheduler_disabled
    return not frappe.utils.cint(frappe.db.get_single_value("System Settings", "enable_scheduler"))
  File "/home/brenda/Desktop/frappe-bench/apps/frappe/frappe/database/database.py", line 550, in get_single_value
    `tabSingles` where `doctype`=%s and `field`=%s""", (doctype, fieldname))
  File "/home/brenda/Desktop/frappe-bench/apps/frappe/frappe/database/database.py", line 111, in sql
    self.connect()
  File "/home/brenda/Desktop/frappe-bench/apps/frappe/frappe/database/database.py", line 64, in connect
    self._conn = self.get_connection()
  File "/home/brenda/Desktop/frappe-bench/apps/frappe/frappe/database/mariadb/database.py", line 80, in get_connection
    local_infile=frappe.conf.local_infile
  File "/home/brenda/Desktop/frappe-bench/env/lib/python3.6/site-packages/pymysql/connections.py", line 353, in __init__
    self.connect()
  File "/home/brenda/Desktop/frappe-bench/env/lib/python3.6/site-packages/pymysql/connections.py", line 664, in connect
    raise exc
pymysql.err.OperationalError: (2003, "Can't connect to MySQL server on '127.0.0.1' ([Errno 111] Connection refused)")

2021-07-13 13:49:08,495 ERROR scheduler Exception in Enqueue Events for Site library.test
Traceback (most recent call last):
  File "/home/brenda/Desktop/frappe-bench/env/lib/python3.6/site-packages/pymysql/connections.py", line 614, in connect
    (self.host, self.port), self.connect_timeout, **kwargs
  File "/usr/lib/python3.6/socket.py", line 724, in create_connection
    raise err
  File "/usr/lib/python3.6/socket.py", line 713, in create_connection
    sock.connect(sa)
ConnectionRefusedError: [Errno 111] Connection refused

During handling of the above exception, another exception occurred:

Traceback (most recent call last):
  File "/home/brenda/Desktop/frappe-bench/apps/frappe/frappe/utils/scheduler.py", line 62, in enqueue_events_for_site
    if is_scheduler_inactive():
  File "/home/brenda/Desktop/frappe-bench/apps/frappe/frappe/utils/scheduler.py", line 95, in is_scheduler_inactive
    if is_scheduler_disabled():
  File "/home/brenda/Desktop/frappe-bench/apps/frappe/frappe/utils/scheduler.py", line 104, in is_scheduler_disabled
    return not frappe.utils.cint(frappe.db.get_single_value("System Settings", "enable_scheduler"))
  File "/home/brenda/Desktop/frappe-bench/apps/frappe/frappe/database/database.py", line 550, in get_single_value
    `tabSingles` where `doctype`=%s and `field`=%s""", (doctype, fieldname))
  File "/home/brenda/Desktop/frappe-bench/apps/frappe/frappe/database/database.py", line 111, in sql
    self.connect()
  File "/home/brenda/Desktop/frappe-bench/apps/frappe/frappe/database/database.py", line 64, in connect
    self._conn = self.get_connection()
  File "/home/brenda/Desktop/frappe-bench/apps/frappe/frappe/database/mariadb/database.py", line 80, in get_connection
    local_infile=frappe.conf.local_infile
  File "/home/brenda/Desktop/frappe-bench/env/lib/python3.6/site-packages/pymysql/connections.py", line 353, in __init__
    self.connect()
  File "/home/brenda/Desktop/frappe-bench/env/lib/python3.6/site-packages/pymysql/connections.py", line 664, in connect
    raise exc
pymysql.err.OperationalError: (2003, "Can't connect to MySQL server on '127.0.0.1' ([Errno 111] Connection refused)")

2021-07-13 13:50:08,574 ERROR scheduler Exception in Enqueue Events for Site library.test
Traceback (most recent call last):
  File "/home/brenda/Desktop/frappe-bench/env/lib/python3.6/site-packages/pymysql/connections.py", line 614, in connect
    (self.host, self.port), self.connect_timeout, **kwargs
  File "/usr/lib/python3.6/socket.py", line 724, in create_connection
    raise err
  File "/usr/lib/python3.6/socket.py", line 713, in create_connection
    sock.connect(sa)
ConnectionRefusedError: [Errno 111] Connection refused

During handling of the above exception, another exception occurred:

Traceback (most recent call last):
  File "/home/brenda/Desktop/frappe-bench/apps/frappe/frappe/utils/scheduler.py", line 62, in enqueue_events_for_site
    if is_scheduler_inactive():
  File "/home/brenda/Desktop/frappe-bench/apps/frappe/frappe/utils/scheduler.py", line 95, in is_scheduler_inactive
    if is_scheduler_disabled():
  File "/home/brenda/Desktop/frappe-bench/apps/frappe/frappe/utils/scheduler.py", line 104, in is_scheduler_disabled
    return not frappe.utils.cint(frappe.db.get_single_value("System Settings", "enable_scheduler"))
  File "/home/brenda/Desktop/frappe-bench/apps/frappe/frappe/database/database.py", line 550, in get_single_value
    `tabSingles` where `doctype`=%s and `field`=%s""", (doctype, fieldname))
  File "/home/brenda/Desktop/frappe-bench/apps/frappe/frappe/database/database.py", line 111, in sql
    self.connect()
  File "/home/brenda/Desktop/frappe-bench/apps/frappe/frappe/database/database.py", line 64, in connect
    self._conn = self.get_connection()
  File "/home/brenda/Desktop/frappe-bench/apps/frappe/frappe/database/mariadb/database.py", line 80, in get_connection
    local_infile=frappe.conf.local_infile
  File "/home/brenda/Desktop/frappe-bench/env/lib/python3.6/site-packages/pymysql/connections.py", line 353, in __init__
    self.connect()
  File "/home/brenda/Desktop/frappe-bench/env/lib/python3.6/site-packages/pymysql/connections.py", line 664, in connect
    raise exc
pymysql.err.OperationalError: (2003, "Can't connect to MySQL server on '127.0.0.1' ([Errno 111] Connection refused)")

2021-07-13 13:51:08,657 ERROR scheduler Exception in Enqueue Events for Site library.test
Traceback (most recent call last):
  File "/home/brenda/Desktop/frappe-bench/env/lib/python3.6/site-packages/pymysql/connections.py", line 614, in connect
    (self.host, self.port), self.connect_timeout, **kwargs
  File "/usr/lib/python3.6/socket.py", line 724, in create_connection
    raise err
  File "/usr/lib/python3.6/socket.py", line 713, in create_connection
    sock.connect(sa)
ConnectionRefusedError: [Errno 111] Connection refused

During handling of the above exception, another exception occurred:

Traceback (most recent call last):
  File "/home/brenda/Desktop/frappe-bench/apps/frappe/frappe/utils/scheduler.py", line 62, in enqueue_events_for_site
    if is_scheduler_inactive():
  File "/home/brenda/Desktop/frappe-bench/apps/frappe/frappe/utils/scheduler.py", line 95, in is_scheduler_inactive
    if is_scheduler_disabled():
  File "/home/brenda/Desktop/frappe-bench/apps/frappe/frappe/utils/scheduler.py", line 104, in is_scheduler_disabled
    return not frappe.utils.cint(frappe.db.get_single_value("System Settings", "enable_scheduler"))
  File "/home/brenda/Desktop/frappe-bench/apps/frappe/frappe/database/database.py", line 550, in get_single_value
    `tabSingles` where `doctype`=%s and `field`=%s""", (doctype, fieldname))
  File "/home/brenda/Desktop/frappe-bench/apps/frappe/frappe/database/database.py", line 111, in sql
    self.connect()
  File "/home/brenda/Desktop/frappe-bench/apps/frappe/frappe/database/database.py", line 64, in connect
    self._conn = self.get_connection()
  File "/home/brenda/Desktop/frappe-bench/apps/frappe/frappe/database/mariadb/database.py", line 80, in get_connection
    local_infile=frappe.conf.local_infile
  File "/home/brenda/Desktop/frappe-bench/env/lib/python3.6/site-packages/pymysql/connections.py", line 353, in __init__
    self.connect()
  File "/home/brenda/Desktop/frappe-bench/env/lib/python3.6/site-packages/pymysql/connections.py", line 664, in connect
    raise exc
pymysql.err.OperationalError: (2003, "Can't connect to MySQL server on '127.0.0.1' ([Errno 111] Connection refused)")

2021-07-13 13:52:08,729 ERROR scheduler Exception in Enqueue Events for Site library.test
Traceback (most recent call last):
  File "/home/brenda/Desktop/frappe-bench/env/lib/python3.6/site-packages/pymysql/connections.py", line 614, in connect
    (self.host, self.port), self.connect_timeout, **kwargs
  File "/usr/lib/python3.6/socket.py", line 724, in create_connection
    raise err
  File "/usr/lib/python3.6/socket.py", line 713, in create_connection
    sock.connect(sa)
ConnectionRefusedError: [Errno 111] Connection refused

During handling of the above exception, another exception occurred:

Traceback (most recent call last):
  File "/home/brenda/Desktop/frappe-bench/apps/frappe/frappe/utils/scheduler.py", line 62, in enqueue_events_for_site
    if is_scheduler_inactive():
  File "/home/brenda/Desktop/frappe-bench/apps/frappe/frappe/utils/scheduler.py", line 95, in is_scheduler_inactive
    if is_scheduler_disabled():
  File "/home/brenda/Desktop/frappe-bench/apps/frappe/frappe/utils/scheduler.py", line 104, in is_scheduler_disabled
    return not frappe.utils.cint(frappe.db.get_single_value("System Settings", "enable_scheduler"))
  File "/home/brenda/Desktop/frappe-bench/apps/frappe/frappe/database/database.py", line 550, in get_single_value
    `tabSingles` where `doctype`=%s and `field`=%s""", (doctype, fieldname))
  File "/home/brenda/Desktop/frappe-bench/apps/frappe/frappe/database/database.py", line 111, in sql
    self.connect()
  File "/home/brenda/Desktop/frappe-bench/apps/frappe/frappe/database/database.py", line 64, in connect
    self._conn = self.get_connection()
  File "/home/brenda/Desktop/frappe-bench/apps/frappe/frappe/database/mariadb/database.py", line 80, in get_connection
    local_infile=frappe.conf.local_infile
  File "/home/brenda/Desktop/frappe-bench/env/lib/python3.6/site-packages/pymysql/connections.py", line 353, in __init__
    self.connect()
  File "/home/brenda/Desktop/frappe-bench/env/lib/python3.6/site-packages/pymysql/connections.py", line 664, in connect
    raise exc
pymysql.err.OperationalError: (2003, "Can't connect to MySQL server on '127.0.0.1' ([Errno 111] Connection refused)")

2021-07-13 13:53:08,807 ERROR scheduler Exception in Enqueue Events for Site library.test
Traceback (most recent call last):
  File "/home/brenda/Desktop/frappe-bench/env/lib/python3.6/site-packages/pymysql/connections.py", line 614, in connect
    (self.host, self.port), self.connect_timeout, **kwargs
  File "/usr/lib/python3.6/socket.py", line 724, in create_connection
    raise err
  File "/usr/lib/python3.6/socket.py", line 713, in create_connection
    sock.connect(sa)
ConnectionRefusedError: [Errno 111] Connection refused

During handling of the above exception, another exception occurred:

Traceback (most recent call last):
  File "/home/brenda/Desktop/frappe-bench/apps/frappe/frappe/utils/scheduler.py", line 62, in enqueue_events_for_site
    if is_scheduler_inactive():
  File "/home/brenda/Desktop/frappe-bench/apps/frappe/frappe/utils/scheduler.py", line 95, in is_scheduler_inactive
    if is_scheduler_disabled():
  File "/home/brenda/Desktop/frappe-bench/apps/frappe/frappe/utils/scheduler.py", line 104, in is_scheduler_disabled
    return not frappe.utils.cint(frappe.db.get_single_value("System Settings", "enable_scheduler"))
  File "/home/brenda/Desktop/frappe-bench/apps/frappe/frappe/database/database.py", line 550, in get_single_value
    `tabSingles` where `doctype`=%s and `field`=%s""", (doctype, fieldname))
  File "/home/brenda/Desktop/frappe-bench/apps/frappe/frappe/database/database.py", line 111, in sql
    self.connect()
  File "/home/brenda/Desktop/frappe-bench/apps/frappe/frappe/database/database.py", line 64, in connect
    self._conn = self.get_connection()
  File "/home/brenda/Desktop/frappe-bench/apps/frappe/frappe/database/mariadb/database.py", line 80, in get_connection
    local_infile=frappe.conf.local_infile
  File "/home/brenda/Desktop/frappe-bench/env/lib/python3.6/site-packages/pymysql/connections.py", line 353, in __init__
    self.connect()
  File "/home/brenda/Desktop/frappe-bench/env/lib/python3.6/site-packages/pymysql/connections.py", line 664, in connect
    raise exc
pymysql.err.OperationalError: (2003, "Can't connect to MySQL server on '127.0.0.1' ([Errno 111] Connection refused)")

2021-07-13 13:54:08,887 ERROR scheduler Exception in Enqueue Events for Site library.test
Traceback (most recent call last):
  File "/home/brenda/Desktop/frappe-bench/env/lib/python3.6/site-packages/pymysql/connections.py", line 614, in connect
    (self.host, self.port), self.connect_timeout, **kwargs
  File "/usr/lib/python3.6/socket.py", line 724, in create_connection
    raise err
  File "/usr/lib/python3.6/socket.py", line 713, in create_connection
    sock.connect(sa)
ConnectionRefusedError: [Errno 111] Connection refused

During handling of the above exception, another exception occurred:

Traceback (most recent call last):
  File "/home/brenda/Desktop/frappe-bench/apps/frappe/frappe/utils/scheduler.py", line 62, in enqueue_events_for_site
    if is_scheduler_inactive():
  File "/home/brenda/Desktop/frappe-bench/apps/frappe/frappe/utils/scheduler.py", line 95, in is_scheduler_inactive
    if is_scheduler_disabled():
  File "/home/brenda/Desktop/frappe-bench/apps/frappe/frappe/utils/scheduler.py", line 104, in is_scheduler_disabled
    return not frappe.utils.cint(frappe.db.get_single_value("System Settings", "enable_scheduler"))
  File "/home/brenda/Desktop/frappe-bench/apps/frappe/frappe/database/database.py", line 550, in get_single_value
    `tabSingles` where `doctype`=%s and `field`=%s""", (doctype, fieldname))
  File "/home/brenda/Desktop/frappe-bench/apps/frappe/frappe/database/database.py", line 111, in sql
    self.connect()
  File "/home/brenda/Desktop/frappe-bench/apps/frappe/frappe/database/database.py", line 64, in connect
    self._conn = self.get_connection()
  File "/home/brenda/Desktop/frappe-bench/apps/frappe/frappe/database/mariadb/database.py", line 80, in get_connection
    local_infile=frappe.conf.local_infile
  File "/home/brenda/Desktop/frappe-bench/env/lib/python3.6/site-packages/pymysql/connections.py", line 353, in __init__
    self.connect()
  File "/home/brenda/Desktop/frappe-bench/env/lib/python3.6/site-packages/pymysql/connections.py", line 664, in connect
    raise exc
pymysql.err.OperationalError: (2003, "Can't connect to MySQL server on '127.0.0.1' ([Errno 111] Connection refused)")

2021-07-13 13:55:08,965 ERROR scheduler Exception in Enqueue Events for Site library.test
Traceback (most recent call last):
  File "/home/brenda/Desktop/frappe-bench/env/lib/python3.6/site-packages/pymysql/connections.py", line 614, in connect
    (self.host, self.port), self.connect_timeout, **kwargs
  File "/usr/lib/python3.6/socket.py", line 724, in create_connection
    raise err
  File "/usr/lib/python3.6/socket.py", line 713, in create_connection
    sock.connect(sa)
ConnectionRefusedError: [Errno 111] Connection refused

During handling of the above exception, another exception occurred:

Traceback (most recent call last):
  File "/home/brenda/Desktop/frappe-bench/apps/frappe/frappe/utils/scheduler.py", line 62, in enqueue_events_for_site
    if is_scheduler_inactive():
  File "/home/brenda/Desktop/frappe-bench/apps/frappe/frappe/utils/scheduler.py", line 95, in is_scheduler_inactive
    if is_scheduler_disabled():
  File "/home/brenda/Desktop/frappe-bench/apps/frappe/frappe/utils/scheduler.py", line 104, in is_scheduler_disabled
    return not frappe.utils.cint(frappe.db.get_single_value("System Settings", "enable_scheduler"))
  File "/home/brenda/Desktop/frappe-bench/apps/frappe/frappe/database/database.py", line 550, in get_single_value
    `tabSingles` where `doctype`=%s and `field`=%s""", (doctype, fieldname))
  File "/home/brenda/Desktop/frappe-bench/apps/frappe/frappe/database/database.py", line 111, in sql
    self.connect()
  File "/home/brenda/Desktop/frappe-bench/apps/frappe/frappe/database/database.py", line 64, in connect
    self._conn = self.get_connection()
  File "/home/brenda/Desktop/frappe-bench/apps/frappe/frappe/database/mariadb/database.py", line 80, in get_connection
    local_infile=frappe.conf.local_infile
  File "/home/brenda/Desktop/frappe-bench/env/lib/python3.6/site-packages/pymysql/connections.py", line 353, in __init__
    self.connect()
  File "/home/brenda/Desktop/frappe-bench/env/lib/python3.6/site-packages/pymysql/connections.py", line 664, in connect
    raise exc
pymysql.err.OperationalError: (2003, "Can't connect to MySQL server on '127.0.0.1' ([Errno 111] Connection refused)")

2021-07-13 13:56:09,045 ERROR scheduler Exception in Enqueue Events for Site library.test
Traceback (most recent call last):
  File "/home/brenda/Desktop/frappe-bench/env/lib/python3.6/site-packages/pymysql/connections.py", line 614, in connect
    (self.host, self.port), self.connect_timeout, **kwargs
  File "/usr/lib/python3.6/socket.py", line 724, in create_connection
    raise err
  File "/usr/lib/python3.6/socket.py", line 713, in create_connection
    sock.connect(sa)
ConnectionRefusedError: [Errno 111] Connection refused

During handling of the above exception, another exception occurred:

Traceback (most recent call last):
  File "/home/brenda/Desktop/frappe-bench/apps/frappe/frappe/utils/scheduler.py", line 62, in enqueue_events_for_site
    if is_scheduler_inactive():
  File "/home/brenda/Desktop/frappe-bench/apps/frappe/frappe/utils/scheduler.py", line 95, in is_scheduler_inactive
    if is_scheduler_disabled():
  File "/home/brenda/Desktop/frappe-bench/apps/frappe/frappe/utils/scheduler.py", line 104, in is_scheduler_disabled
    return not frappe.utils.cint(frappe.db.get_single_value("System Settings", "enable_scheduler"))
  File "/home/brenda/Desktop/frappe-bench/apps/frappe/frappe/database/database.py", line 550, in get_single_value
    `tabSingles` where `doctype`=%s and `field`=%s""", (doctype, fieldname))
  File "/home/brenda/Desktop/frappe-bench/apps/frappe/frappe/database/database.py", line 111, in sql
    self.connect()
  File "/home/brenda/Desktop/frappe-bench/apps/frappe/frappe/database/database.py", line 64, in connect
    self._conn = self.get_connection()
  File "/home/brenda/Desktop/frappe-bench/apps/frappe/frappe/database/mariadb/database.py", line 80, in get_connection
    local_infile=frappe.conf.local_infile
  File "/home/brenda/Desktop/frappe-bench/env/lib/python3.6/site-packages/pymysql/connections.py", line 353, in __init__
    self.connect()
  File "/home/brenda/Desktop/frappe-bench/env/lib/python3.6/site-packages/pymysql/connections.py", line 664, in connect
    raise exc
pymysql.err.OperationalError: (2003, "Can't connect to MySQL server on '127.0.0.1' ([Errno 111] Connection refused)")

2021-07-13 13:57:09,126 ERROR scheduler Exception in Enqueue Events for Site library.test
Traceback (most recent call last):
  File "/home/brenda/Desktop/frappe-bench/env/lib/python3.6/site-packages/pymysql/connections.py", line 614, in connect
    (self.host, self.port), self.connect_timeout, **kwargs
  File "/usr/lib/python3.6/socket.py", line 724, in create_connection
    raise err
  File "/usr/lib/python3.6/socket.py", line 713, in create_connection
    sock.connect(sa)
ConnectionRefusedError: [Errno 111] Connection refused

During handling of the above exception, another exception occurred:

Traceback (most recent call last):
  File "/home/brenda/Desktop/frappe-bench/apps/frappe/frappe/utils/scheduler.py", line 62, in enqueue_events_for_site
    if is_scheduler_inactive():
  File "/home/brenda/Desktop/frappe-bench/apps/frappe/frappe/utils/scheduler.py", line 95, in is_scheduler_inactive
    if is_scheduler_disabled():
  File "/home/brenda/Desktop/frappe-bench/apps/frappe/frappe/utils/scheduler.py", line 104, in is_scheduler_disabled
    return not frappe.utils.cint(frappe.db.get_single_value("System Settings", "enable_scheduler"))
  File "/home/brenda/Desktop/frappe-bench/apps/frappe/frappe/database/database.py", line 550, in get_single_value
    `tabSingles` where `doctype`=%s and `field`=%s""", (doctype, fieldname))
  File "/home/brenda/Desktop/frappe-bench/apps/frappe/frappe/database/database.py", line 111, in sql
    self.connect()
  File "/home/brenda/Desktop/frappe-bench/apps/frappe/frappe/database/database.py", line 64, in connect
    self._conn = self.get_connection()
  File "/home/brenda/Desktop/frappe-bench/apps/frappe/frappe/database/mariadb/database.py", line 80, in get_connection
    local_infile=frappe.conf.local_infile
  File "/home/brenda/Desktop/frappe-bench/env/lib/python3.6/site-packages/pymysql/connections.py", line 353, in __init__
    self.connect()
  File "/home/brenda/Desktop/frappe-bench/env/lib/python3.6/site-packages/pymysql/connections.py", line 664, in connect
    raise exc
pymysql.err.OperationalError: (2003, "Can't connect to MySQL server on '127.0.0.1' ([Errno 111] Connection refused)")

2021-07-13 13:58:09,204 ERROR scheduler Exception in Enqueue Events for Site library.test
Traceback (most recent call last):
  File "/home/brenda/Desktop/frappe-bench/env/lib/python3.6/site-packages/pymysql/connections.py", line 614, in connect
    (self.host, self.port), self.connect_timeout, **kwargs
  File "/usr/lib/python3.6/socket.py", line 724, in create_connection
    raise err
  File "/usr/lib/python3.6/socket.py", line 713, in create_connection
    sock.connect(sa)
ConnectionRefusedError: [Errno 111] Connection refused

During handling of the above exception, another exception occurred:

Traceback (most recent call last):
  File "/home/brenda/Desktop/frappe-bench/apps/frappe/frappe/utils/scheduler.py", line 62, in enqueue_events_for_site
    if is_scheduler_inactive():
  File "/home/brenda/Desktop/frappe-bench/apps/frappe/frappe/utils/scheduler.py", line 95, in is_scheduler_inactive
    if is_scheduler_disabled():
  File "/home/brenda/Desktop/frappe-bench/apps/frappe/frappe/utils/scheduler.py", line 104, in is_scheduler_disabled
    return not frappe.utils.cint(frappe.db.get_single_value("System Settings", "enable_scheduler"))
  File "/home/brenda/Desktop/frappe-bench/apps/frappe/frappe/database/database.py", line 550, in get_single_value
    `tabSingles` where `doctype`=%s and `field`=%s""", (doctype, fieldname))
  File "/home/brenda/Desktop/frappe-bench/apps/frappe/frappe/database/database.py", line 111, in sql
    self.connect()
  File "/home/brenda/Desktop/frappe-bench/apps/frappe/frappe/database/database.py", line 64, in connect
    self._conn = self.get_connection()
  File "/home/brenda/Desktop/frappe-bench/apps/frappe/frappe/database/mariadb/database.py", line 80, in get_connection
    local_infile=frappe.conf.local_infile
  File "/home/brenda/Desktop/frappe-bench/env/lib/python3.6/site-packages/pymysql/connections.py", line 353, in __init__
    self.connect()
  File "/home/brenda/Desktop/frappe-bench/env/lib/python3.6/site-packages/pymysql/connections.py", line 664, in connect
    raise exc
pymysql.err.OperationalError: (2003, "Can't connect to MySQL server on '127.0.0.1' ([Errno 111] Connection refused)")

2021-07-13 13:59:09,272 ERROR scheduler Exception in Enqueue Events for Site library.test
Traceback (most recent call last):
  File "/home/brenda/Desktop/frappe-bench/env/lib/python3.6/site-packages/pymysql/connections.py", line 614, in connect
    (self.host, self.port), self.connect_timeout, **kwargs
  File "/usr/lib/python3.6/socket.py", line 724, in create_connection
    raise err
  File "/usr/lib/python3.6/socket.py", line 713, in create_connection
    sock.connect(sa)
ConnectionRefusedError: [Errno 111] Connection refused

During handling of the above exception, another exception occurred:

Traceback (most recent call last):
  File "/home/brenda/Desktop/frappe-bench/apps/frappe/frappe/utils/scheduler.py", line 62, in enqueue_events_for_site
    if is_scheduler_inactive():
  File "/home/brenda/Desktop/frappe-bench/apps/frappe/frappe/utils/scheduler.py", line 95, in is_scheduler_inactive
    if is_scheduler_disabled():
  File "/home/brenda/Desktop/frappe-bench/apps/frappe/frappe/utils/scheduler.py", line 104, in is_scheduler_disabled
    return not frappe.utils.cint(frappe.db.get_single_value("System Settings", "enable_scheduler"))
  File "/home/brenda/Desktop/frappe-bench/apps/frappe/frappe/database/database.py", line 550, in get_single_value
    `tabSingles` where `doctype`=%s and `field`=%s""", (doctype, fieldname))
  File "/home/brenda/Desktop/frappe-bench/apps/frappe/frappe/database/database.py", line 111, in sql
    self.connect()
  File "/home/brenda/Desktop/frappe-bench/apps/frappe/frappe/database/database.py", line 64, in connect
    self._conn = self.get_connection()
  File "/home/brenda/Desktop/frappe-bench/apps/frappe/frappe/database/mariadb/database.py", line 80, in get_connection
    local_infile=frappe.conf.local_infile
  File "/home/brenda/Desktop/frappe-bench/env/lib/python3.6/site-packages/pymysql/connections.py", line 353, in __init__
    self.connect()
  File "/home/brenda/Desktop/frappe-bench/env/lib/python3.6/site-packages/pymysql/connections.py", line 664, in connect
    raise exc
pymysql.err.OperationalError: (2003, "Can't connect to MySQL server on '127.0.0.1' ([Errno 111] Connection refused)")

2021-07-13 14:00:09,336 ERROR scheduler Exception in Enqueue Events for Site library.test
Traceback (most recent call last):
  File "/home/brenda/Desktop/frappe-bench/env/lib/python3.6/site-packages/pymysql/connections.py", line 614, in connect
    (self.host, self.port), self.connect_timeout, **kwargs
  File "/usr/lib/python3.6/socket.py", line 724, in create_connection
    raise err
  File "/usr/lib/python3.6/socket.py", line 713, in create_connection
    sock.connect(sa)
ConnectionRefusedError: [Errno 111] Connection refused

During handling of the above exception, another exception occurred:

Traceback (most recent call last):
  File "/home/brenda/Desktop/frappe-bench/apps/frappe/frappe/utils/scheduler.py", line 62, in enqueue_events_for_site
    if is_scheduler_inactive():
  File "/home/brenda/Desktop/frappe-bench/apps/frappe/frappe/utils/scheduler.py", line 95, in is_scheduler_inactive
    if is_scheduler_disabled():
  File "/home/brenda/Desktop/frappe-bench/apps/frappe/frappe/utils/scheduler.py", line 104, in is_scheduler_disabled
    return not frappe.utils.cint(frappe.db.get_single_value("System Settings", "enable_scheduler"))
  File "/home/brenda/Desktop/frappe-bench/apps/frappe/frappe/database/database.py", line 550, in get_single_value
    `tabSingles` where `doctype`=%s and `field`=%s""", (doctype, fieldname))
  File "/home/brenda/Desktop/frappe-bench/apps/frappe/frappe/database/database.py", line 111, in sql
    self.connect()
  File "/home/brenda/Desktop/frappe-bench/apps/frappe/frappe/database/database.py", line 64, in connect
    self._conn = self.get_connection()
  File "/home/brenda/Desktop/frappe-bench/apps/frappe/frappe/database/mariadb/database.py", line 80, in get_connection
    local_infile=frappe.conf.local_infile
  File "/home/brenda/Desktop/frappe-bench/env/lib/python3.6/site-packages/pymysql/connections.py", line 353, in __init__
    self.connect()
  File "/home/brenda/Desktop/frappe-bench/env/lib/python3.6/site-packages/pymysql/connections.py", line 664, in connect
    raise exc
pymysql.err.OperationalError: (2003, "Can't connect to MySQL server on '127.0.0.1' ([Errno 111] Connection refused)")

2021-07-13 14:01:09,398 ERROR scheduler Exception in Enqueue Events for Site library.test
Traceback (most recent call last):
  File "/home/brenda/Desktop/frappe-bench/env/lib/python3.6/site-packages/pymysql/connections.py", line 614, in connect
    (self.host, self.port), self.connect_timeout, **kwargs
  File "/usr/lib/python3.6/socket.py", line 724, in create_connection
    raise err
  File "/usr/lib/python3.6/socket.py", line 713, in create_connection
    sock.connect(sa)
ConnectionRefusedError: [Errno 111] Connection refused

During handling of the above exception, another exception occurred:

Traceback (most recent call last):
  File "/home/brenda/Desktop/frappe-bench/apps/frappe/frappe/utils/scheduler.py", line 62, in enqueue_events_for_site
    if is_scheduler_inactive():
  File "/home/brenda/Desktop/frappe-bench/apps/frappe/frappe/utils/scheduler.py", line 95, in is_scheduler_inactive
    if is_scheduler_disabled():
  File "/home/brenda/Desktop/frappe-bench/apps/frappe/frappe/utils/scheduler.py", line 104, in is_scheduler_disabled
    return not frappe.utils.cint(frappe.db.get_single_value("System Settings", "enable_scheduler"))
  File "/home/brenda/Desktop/frappe-bench/apps/frappe/frappe/database/database.py", line 550, in get_single_value
    `tabSingles` where `doctype`=%s and `field`=%s""", (doctype, fieldname))
  File "/home/brenda/Desktop/frappe-bench/apps/frappe/frappe/database/database.py", line 111, in sql
    self.connect()
  File "/home/brenda/Desktop/frappe-bench/apps/frappe/frappe/database/database.py", line 64, in connect
    self._conn = self.get_connection()
  File "/home/brenda/Desktop/frappe-bench/apps/frappe/frappe/database/mariadb/database.py", line 80, in get_connection
    local_infile=frappe.conf.local_infile
  File "/home/brenda/Desktop/frappe-bench/env/lib/python3.6/site-packages/pymysql/connections.py", line 353, in __init__
    self.connect()
  File "/home/brenda/Desktop/frappe-bench/env/lib/python3.6/site-packages/pymysql/connections.py", line 664, in connect
    raise exc
pymysql.err.OperationalError: (2003, "Can't connect to MySQL server on '127.0.0.1' ([Errno 111] Connection refused)")

2021-07-13 14:02:09,464 ERROR scheduler Exception in Enqueue Events for Site library.test
Traceback (most recent call last):
  File "/home/brenda/Desktop/frappe-bench/env/lib/python3.6/site-packages/pymysql/connections.py", line 614, in connect
    (self.host, self.port), self.connect_timeout, **kwargs
  File "/usr/lib/python3.6/socket.py", line 724, in create_connection
    raise err
  File "/usr/lib/python3.6/socket.py", line 713, in create_connection
    sock.connect(sa)
ConnectionRefusedError: [Errno 111] Connection refused

During handling of the above exception, another exception occurred:

Traceback (most recent call last):
  File "/home/brenda/Desktop/frappe-bench/apps/frappe/frappe/utils/scheduler.py", line 62, in enqueue_events_for_site
    if is_scheduler_inactive():
  File "/home/brenda/Desktop/frappe-bench/apps/frappe/frappe/utils/scheduler.py", line 95, in is_scheduler_inactive
    if is_scheduler_disabled():
  File "/home/brenda/Desktop/frappe-bench/apps/frappe/frappe/utils/scheduler.py", line 104, in is_scheduler_disabled
    return not frappe.utils.cint(frappe.db.get_single_value("System Settings", "enable_scheduler"))
  File "/home/brenda/Desktop/frappe-bench/apps/frappe/frappe/database/database.py", line 550, in get_single_value
    `tabSingles` where `doctype`=%s and `field`=%s""", (doctype, fieldname))
  File "/home/brenda/Desktop/frappe-bench/apps/frappe/frappe/database/database.py", line 111, in sql
    self.connect()
  File "/home/brenda/Desktop/frappe-bench/apps/frappe/frappe/database/database.py", line 64, in connect
    self._conn = self.get_connection()
  File "/home/brenda/Desktop/frappe-bench/apps/frappe/frappe/database/mariadb/database.py", line 80, in get_connection
    local_infile=frappe.conf.local_infile
  File "/home/brenda/Desktop/frappe-bench/env/lib/python3.6/site-packages/pymysql/connections.py", line 353, in __init__
    self.connect()
  File "/home/brenda/Desktop/frappe-bench/env/lib/python3.6/site-packages/pymysql/connections.py", line 664, in connect
    raise exc
pymysql.err.OperationalError: (2003, "Can't connect to MySQL server on '127.0.0.1' ([Errno 111] Connection refused)")

